2021-02-05 06:06:39,934:WARNING:discord.client: PyNaCl is not installed, voice will NOT be supported
2021-02-05 06:11:36,567:WARNING:discord.client: PyNaCl is not installed, voice will NOT be supported
2021-02-05 06:14:40,059:WARNING:discord.client: PyNaCl is not installed, voice will NOT be supported
2021-02-05 06:15:48,926:WARNING:discord.client: PyNaCl is not installed, voice will NOT be supported
2021-02-05 06:35:39,276:WARNING:discord.client: PyNaCl is not installed, voice will NOT be supported
2021-02-11 10:35:20,458:ERROR:discord.client: Attempting a reconnect in 0.44s
Traceback (most recent call last):
  File "/usr/local/lib/python3.7/dist-packages/discord/client.py", line 561, in connect
    await self.ws.poll_event()
  File "/usr/local/lib/python3.7/dist-packages/discord/gateway.py", line 587, in poll_event
    raise ConnectionClosed(self.socket, shard_id=self.shard_id, code=code) from None
discord.errors.ConnectionClosed: Shard ID None WebSocket closed with 1000
2021-02-16 04:50:40,560:ERROR:discord.client: Attempting a reconnect in 0.58s
Traceback (most recent call last):
  File "/usr/local/lib/python3.7/dist-packages/discord/client.py", line 561, in connect
    await self.ws.poll_event()
  File "/usr/local/lib/python3.7/dist-packages/discord/gateway.py", line 587, in poll_event
    raise ConnectionClosed(self.socket, shard_id=self.shard_id, code=code) from None
discord.errors.ConnectionClosed: Shard ID None WebSocket closed with 1000
2021-02-19 03:15:44,186:ERROR:discord.client: Attempting a reconnect in 1.07s
Traceback (most recent call last):
  File "/usr/local/lib/python3.7/dist-packages/discord/client.py", line 558, in connect
    self.ws = await asyncio.wait_for(coro, timeout=60.0)
  File "/usr/lib/python3.7/asyncio/tasks.py", line 423, in wait_for
    raise futures.TimeoutError()
concurrent.futures._base.TimeoutError
2021-02-19 03:17:33,746:ERROR:discord.client: Attempting a reconnect in 0.32s
Traceback (most recent call last):
  File "/usr/local/lib/python3.7/dist-packages/discord/client.py", line 558, in connect
    self.ws = await asyncio.wait_for(coro, timeout=60.0)
  File "/usr/lib/python3.7/asyncio/tasks.py", line 423, in wait_for
    raise futures.TimeoutError()
concurrent.futures._base.TimeoutError
2021-02-19 03:18:34,094:ERROR:discord.client: Attempting a reconnect in 2.69s
Traceback (most recent call last):
  File "/usr/local/lib/python3.7/dist-packages/discord/client.py", line 558, in connect
    self.ws = await asyncio.wait_for(coro, timeout=60.0)
  File "/usr/lib/python3.7/asyncio/tasks.py", line 423, in wait_for
    raise futures.TimeoutError()
concurrent.futures._base.TimeoutError
2021-02-19 03:19:36,801:ERROR:discord.client: Attempting a reconnect in 3.56s
Traceback (most recent call last):
  File "/usr/local/lib/python3.7/dist-packages/discord/client.py", line 558, in connect
    self.ws = await asyncio.wait_for(coro, timeout=60.0)
  File "/usr/lib/python3.7/asyncio/tasks.py", line 423, in wait_for
    raise futures.TimeoutError()
concurrent.futures._base.TimeoutError
2021-02-19 03:20:40,387:ERROR:discord.client: Attempting a reconnect in 18.82s
Traceback (most recent call last):
  File "/usr/local/lib/python3.7/dist-packages/discord/client.py", line 558, in connect
    self.ws = await asyncio.wait_for(coro, timeout=60.0)
  File "/usr/lib/python3.7/asyncio/tasks.py", line 423, in wait_for
    raise futures.TimeoutError()
concurrent.futures._base.TimeoutError
2021-02-19 03:21:59,237:ERROR:discord.client: Attempting a reconnect in 29.94s
Traceback (most recent call last):
  File "/usr/local/lib/python3.7/dist-packages/discord/client.py", line 558, in connect
    self.ws = await asyncio.wait_for(coro, timeout=60.0)
  File "/usr/lib/python3.7/asyncio/tasks.py", line 423, in wait_for
    raise futures.TimeoutError()
concurrent.futures._base.TimeoutError
2021-02-19 03:23:29,224:ERROR:discord.client: Attempting a reconnect in 66.30s
Traceback (most recent call last):
  File "/usr/local/lib/python3.7/dist-packages/discord/client.py", line 558, in connect
    self.ws = await asyncio.wait_for(coro, timeout=60.0)
  File "/usr/lib/python3.7/asyncio/tasks.py", line 423, in wait_for
    raise futures.TimeoutError()
concurrent.futures._base.TimeoutError
2021-02-19 03:25:35,624:ERROR:discord.client: Attempting a reconnect in 151.88s
Traceback (most recent call last):
  File "/usr/local/lib/python3.7/dist-packages/discord/client.py", line 558, in connect
    self.ws = await asyncio.wait_for(coro, timeout=60.0)
  File "/usr/lib/python3.7/asyncio/tasks.py", line 423, in wait_for
    raise futures.TimeoutError()
concurrent.futures._base.TimeoutError
2021-02-19 03:29:07,640:ERROR:discord.client: Attempting a reconnect in 387.84s
Traceback (most recent call last):
  File "/usr/local/lib/python3.7/dist-packages/discord/client.py", line 558, in connect
    self.ws = await asyncio.wait_for(coro, timeout=60.0)
  File "/usr/lib/python3.7/asyncio/tasks.py", line 423, in wait_for
    raise futures.TimeoutError()
concurrent.futures._base.TimeoutError
2021-02-19 03:36:35,608:ERROR:discord.client: Attempting a reconnect in 920.06s
Traceback (most recent call last):
  File "/usr/local/lib/python3.7/dist-packages/discord/client.py", line 558, in connect
    self.ws = await asyncio.wait_for(coro, timeout=60.0)
  File "/usr/lib/python3.7/asyncio/tasks.py", line 423, in wait_for
    raise futures.TimeoutError()
concurrent.futures._base.TimeoutError
2021-03-02 16:31:26,903:WARNING:discord.client: PyNaCl is not installed, voice will NOT be supported
